<robot name="XSensStyleModel_template">
	
	<!--LINKS-->
	<!--Link base (1)-->
	<link name="Pelvis">
        <inertial>
            <mass value="PELVISMASS"/>
            <origin xyz="PELVIS_COM_ORIGIN" rpy="0 0 0" />
            <inertia ixx="PELVISINERTIAIXX" iyy="PELVISINERTIAIYY" izz="PELVISINERTIAIZZ" ixy="0" ixz="0" iyz="0"/>
        </inertial>

        <visual>
            <origin xyz="PELVIS_BOX_ORIGIN" rpy="0 0 0" />
            <geometry>
                <box size="PELVIS_BOX_SIZE"/>
            </geometry>
        </visual>

        <collision>
            <origin xyz="PELVIS_BOX_ORIGIN" rpy="0 0 0" />
            <geometry>
                <box size="PELVIS_BOX_SIZE"/>
            </geometry>
        </collision>
    </link>
    <!--Chain from (2) to (7)-->
	<link name="L5">
        <inertial>
            <mass value="L5MASS"/>
            <origin xyz="L5_COM_ORIGIN" rpy="0 0 0" />
            <inertia ixx="L5INERTIAIXX" iyy="L5INERTIAIYY" izz="L5INERTIAIZZ" ixy="0" ixz="0" iyz="0"/>
        </inertial>

        <visual>
            <origin xyz="L5_BOX_ORIGIN" rpy="0 0 0" />
            <geometry>
                <box size="L5_BOX_SIZE"/>
            </geometry>
        </visual>

        <collision>
            <origin xyz="L5_BOX_ORIGIN" rpy="0 0 0" />
            <geometry>
                <box size="L5_BOX_SIZE"/>
            </geometry>
        </collision>
    </link>
	<link name="L3">
        <inertial>
            <mass value="L3MASS"/>
            <origin xyz="L3_COM_ORIGIN" rpy="0 0 0" />
            <inertia ixx="L3INERTIAIXX" iyy="L3INERTIAIYY" izz="L3INERTIAIZZ" ixy="0" ixz="0" iyz="0"/>
        </inertial>

        <visual>
            <origin xyz="L3_BOX_ORIGIN" rpy="0 0 0" />
            <geometry>
                <box size="L3_BOX_SIZE"/>
            </geometry>
        </visual>

        <collision>
            <origin xyz="L3_BOX_ORIGIN" rpy="0 0 0" />
            <geometry>
                <box size="L3_BOX_SIZE"/>
            </geometry>
        </collision>
    </link>
	<link name="T12">
        <inertial>
            <mass value="T12MASS"/>
            <origin xyz="T12_COM_ORIGIN" rpy="0 0 0" />
            <inertia ixx="T12INERTIAIXX" iyy="T12INERTIAIYY" izz="T12INERTIAIZZ" ixy="0" ixz="0" iyz="0"/>
        </inertial>

        <visual>
            <origin xyz="T12_BOX_ORIGIN" rpy="0 0 0" />
            <geometry>
                <box size="T12_BOX_SIZE"/>
            </geometry>
        </visual>

        <collision>
            <origin xyz="T12_BOX_ORIGIN" rpy="0 0 0" />
            <geometry>
                <box size="T12_BOX_SIZE"/>
            </geometry>
        </collision>
    </link>
	<link name="T8">
        <inertial>
            <mass value="T8MASS"/>
            <origin xyz="T8_COM_ORIGIN" rpy="0 0 0" />
            <inertia ixx="T8INERTIAIXX" iyy="T8INERTIAIYY" izz="T8INERTIAIZZ" ixy="0" ixz="0" iyz="0"/>
        </inertial>

        <visual>
            <origin xyz="T8_BOX_ORIGIN" rpy="0 0 0" />
            <geometry>
                <box size="T8_BOX_SIZE"/>
            </geometry>
        </visual>

        <collision>
            <origin xyz="T8_BOX_ORIGIN" rpy="0 0 0" />
            <geometry>
                <box size="T8_BOX_SIZE"/>
            </geometry>
        </collision>
    </link>
	<link name="Neck">
        <inertial>
            <mass value="NECKMASS"/>
            <origin xyz="NECK_COM_ORIGIN" rpy="0 0 0" />
            <inertia ixx="NECKINERTIAIXX" iyy="NECKINERTIAIYY" izz="NECKINERTIAIZZ" ixy="0" ixz="0" iyz="0"/>
        </inertial>

        <visual>
            <origin xyz="NECK_BOX_ORIGIN" rpy="0 0 0" />
            <geometry>
		<cylinder length="NECKHEIGHT" radius="NECKRADIUS"/>
            </geometry>
        </visual>

        <collision>
            <origin xyz="NECK_BOX_ORIGIN" rpy="0 0 0" />
            <geometry>
                <cylinder length="NECKHEIGHT" radius="NECKRADIUS"/>
            </geometry>
        </collision>
    </link>	
	<link name="Head">
        <inertial>
            <mass value="HEADMASS"/>
            <origin xyz="HEAD_COM_ORIGIN" rpy="0 0 0" />
            <inertia ixx="HEADINERTIAIXX" iyy="HEADINERTIAIYY" izz="HEADINERTIAIZZ" ixy="0" ixz="0" iyz="0"/>
        </inertial>

        <visual>
            <origin xyz="HEAD_BOX_ORIGIN" rpy="0 0 0" />
            <geometry>
                <sphere radius="HEADRADIUS"/>
            </geometry>
        </visual>

        <collision>
            <origin xyz="HEAD_BOX_ORIGIN" rpy="0 0 0" />
            <geometry>
                <sphere radius="HEADRADIUS"/>
            </geometry>
        </collision>
    </link>
	<!--Chain from (8) to (11)-->
	<link name="RightShoulder">
        <inertial>
            <mass value="RIGHTSHOULDERMASS"/>
            <origin xyz="RIGHTSHOULDER_COM_ORIGIN" rpy="0 0 0" />
            <inertia ixx="RIGHTSHOULDERINERTIAIXX" iyy="RIGHTSHOULDERINERTIAIYY" izz="RIGHTSHOULDERINERTIAIZZ" ixy="0" ixz="0" iyz="0"/>
        </inertial>

        <visual>
            <origin xyz="RIGHTSHOULDER_BOX_ORIGIN" rpy="1.5708 0 0" />
            <geometry>
                <cylinder length="RIGHTSHOULDERHEIGHT" radius="RIGHTSHOULDERRADIUS"/>
            </geometry>
        </visual>

        <collision>
            <origin xyz="RIGHTSHOULDER_BOX_ORIGIN" rpy="1.5708 0 0" />
            <geometry>
                <cylinder length="RIGHTSHOULDERHEIGHT" radius="RIGHTSHOULDERRADIUS"/>
            </geometry>
        </collision>
    </link>
    <link name="RightUpperArm">
        <inertial>
            <mass value="RIGHTUPPERARMMASS"/>
            <origin xyz="RIGHTUPPERARM_COM_ORIGIN" rpy="0 0 0" />
            <inertia ixx="RIGHTUPPERARMINERTIAIXX" iyy="RIGHTUPPERARMINERTIAIYY" izz="RIGHTUPPERARMINERTIAIZZ" ixy="0" ixz="0" iyz="0"/>
        </inertial>

        <visual>
            <origin xyz="RIGHTUPPERARM_BOX_ORIGIN" rpy="1.5708 0 0" />
            <geometry>
                <cylinder length="RIGHTUPPERARMHEIGHT" radius="RIGHTUPPERARMRADIUS"/>
            </geometry>
        </visual>

        <collision>
            <origin xyz="RIGHTUPPERARM_BOX_ORIGIN" rpy="1.5708 0 0" />
            <geometry>
                <cylinder length="RIGHTUPPERARMHEIGHT" radius="RIGHTUPPERARMRADIUS"/>
            </geometry>
        </collision>
    </link>	
	<link name="RightForeArm">
        <inertial>
            <mass value="RIGHTFOREARMMASS"/>
            <origin xyz="RIGHTFOREARM_COM_ORIGIN" rpy="0 0 0" />
            <inertia ixx="RIGHTFOREARMINERTIAIXX" iyy="RIGHTFOREARMINERTIAIYY" izz="RIGHTFOREARMINERTIAIZZ" ixy="0" ixz="0" iyz="0"/>
        </inertial>

        <visual>
            <origin xyz="RIGHTFOREARM_BOX_ORIGIN" rpy="1.5708 0 0" />
            <geometry>
                <cylinder length="RIGHTFOREARMHEIGHT" radius="RIGHTFOREARMRADIUS"/>
            </geometry>
        </visual>

        <collision>
            <origin xyz="RIGHTFOREARM_BOX_ORIGIN" rpy="1.5708 0 0" />
            <geometry>
                <cylinder length="RIGHTFOREARMHEIGHT" radius="RIGHTFOREARMRADIUS"/>
            </geometry>
        </collision>
    </link>
	<link name="RightHand">
        <inertial>
            <mass value="RIGHTHANDMASS"/>
            <origin xyz="RIGHTHAND_COM_ORIGIN" rpy="0 0 0" />
            <inertia ixx="RIGHTHANDINERTIAIXX" iyy="RIGHTHANDINERTIAIYY" izz="RIGHTHANDINERTIAIZZ" ixy="0" ixz="0" iyz="0"/>
        </inertial>

        <visual>
            <origin xyz="RIGHTHAND_BOX_ORIGIN" rpy="0 0 0" />
            <geometry>
                <box size="RIGHTHAND_BOX_SIZE"/>
            </geometry>
        </visual>

        <collision>
            <origin xyz="RIGHTHAND_BOX_ORIGIN" rpy="0 0 0" />
            <geometry>
                <box size="RIGHTHAND_BOX_SIZE"/>
            </geometry>
        </collision>
    </link>
	<!--Chain from (12) to (15)-->
	<link name="LeftShoulder">
        <inertial>
            <mass value="LEFTSHOULDERMASS"/>
            <origin xyz="LEFTSHOULDER_COM_ORIGIN" rpy="0 0 0" />
            <inertia ixx="LEFTSHOULDERINERTIAIXX" iyy="LEFTSHOULDERINERTIAIYY" izz="LEFTSHOULDERINERTIAIZZ" ixy="0" ixz="0" iyz="0"/>
        </inertial>

        <visual>
            <origin xyz="LEFTSHOULDER_BOX_ORIGIN" rpy="1.5708 0 0" />
            <geometry>
                <cylinder length="LEFTSHOULDERHEIGHT" radius="LEFTSHOULDERRADIUS"/>
            </geometry>
        </visual>

        <collision>
            <origin xyz="LEFTSHOULDER_BOX_ORIGIN" rpy="1.5708 0 0" />
            <geometry>
                <cylinder length="LEFTSHOULDERHEIGHT" radius="LEFTSHOULDERRADIUS"/>
            </geometry>
        </collision>
    </link>
    <link name="LeftUpperArm">
        <inertial>
            <mass value="LEFTUPPERARMMASS"/>
            <origin xyz="LEFTUPPERARM_COM_ORIGIN" rpy="0 0 0" />
            <inertia ixx="LEFTUPPERARMINERTIAIXX" iyy="LEFTUPPERARMINERTIAIYY" izz="LEFTUPPERARMINERTIAIZZ" ixy="0" ixz="0" iyz="0"/>
        </inertial>

        <visual>
            <origin xyz="LEFTUPPERARM_BOX_ORIGIN" rpy="1.5708 0 0" />
            <geometry>
                <cylinder length="LEFTUPPERARMHEIGHT" radius="LEFTUPPERARMRADIUS"/>
            </geometry>
        </visual>

        <collision>
            <origin xyz="LEFTUPPERARM_BOX_ORIGIN" rpy="1.5708 0 0" />
            <geometry>
                <cylinder length="LEFTUPPERARMHEIGHT" radius="LEFTUPPERARMRADIUS"/>
            </geometry>
        </collision>
    </link>	
	<link name="LeftForeArm">
        <inertial>
            <mass value="LEFTFOREARMMASS"/>
            <origin xyz="LEFTFOREARM_COM_ORIGIN" rpy="0 0 0" />
            <inertia ixx="LEFTFOREARMINERTIAIXX" iyy="LEFTFOREARMINERTIAIYY" izz="LEFTFOREARMINERTIAIZZ" ixy="0" ixz="0" iyz="0"/>
        </inertial>

        <visual>
            <origin xyz="LEFTFOREARM_BOX_ORIGIN" rpy="1.5708 0 0" />
            <geometry>
                <cylinder length="LEFTFOREARMHEIGHT" radius="LEFTFOREARMRADIUS"/>
            </geometry>
        </visual>

        <collision>
            <origin xyz="LEFTFOREARM_BOX_ORIGIN" rpy="1.5708 0 0" />
            <geometry>
                <cylinder length="LEFTFOREARMHEIGHT" radius="LEFTFOREARMRADIUS"/>
            </geometry>
        </collision>
    </link>
	<link name="LeftHand">
        <inertial>
            <mass value="LEFTHANDMASS"/>
            <origin xyz="LEFTHAND_COM_ORIGIN" rpy="0 0 0" />
            <inertia ixx="LEFTHANDINERTIAIXX" iyy="LEFTHANDINERTIAIYY" izz="LEFTHANDINERTIAIZZ" ixy="0" ixz="0" iyz="0"/>
        </inertial>

        <visual>
            <origin xyz="LEFTHAND_BOX_ORIGIN" rpy="0 0 0" />
            <geometry>
                <box size="LEFTHAND_BOX_SIZE"/>
            </geometry>
        </visual>

        <collision>
            <origin xyz="LEFTHAND_BOX_ORIGIN" rpy="0 0 0" />
            <geometry>
                <box size="LEFTHAND_BOX_SIZE"/>
            </geometry>
        </collision>
    </link>
	<!--Chain from (16) to (19)-->
    <link name="RightUpperLeg">
        <inertial>
            <mass value="RIGHTUPPERLEGMASS"/>
            <origin xyz="RIGHTUPPERLEG_COM_ORIGIN" rpy="0 0 0" />
            <inertia ixx="RIGHTUPPERLEGINERTIAIXX" iyy="RIGHTUPPERLEGINERTIAIYY" izz="RIGHTUPPERLEGINERTIAIZZ" ixy="0" ixz="0" iyz="0"/>
        </inertial>

        <visual>
            <origin xyz="RIGHTUPPERLEG_BOX_ORIGIN" rpy="0 0 0" />
            <geometry>
                <cylinder length="RIGHTUPPERLEGHEIGHT" radius="RIGHTUPPERLEGRADIUS"/>
            </geometry>
        </visual>

        <collision>
            <origin xyz="RIGHTUPPERLEG_BOX_ORIGIN" rpy="0 0 0" />
            <geometry>
                <cylinder length="RIGHTUPPERLEGHEIGHT" radius="RIGHTUPPERLEGRADIUS"/>
            </geometry>
        </collision>
    </link>
    <link name="RightLowerLeg">
        <inertial>
            <mass value="RIGHTLOWERLEGMASS"/>
            <origin xyz="RIGHTLOWERLEG_COM_ORIGIN" rpy="0 0 0" />
            <inertia ixx="RIGHTLOWERLEGINERTIAIXX" iyy="RIGHTLOWERLEGINERTIAIYY" izz="RIGHTLOWERLEGINERTIAIZZ" ixy="0" ixz="0" iyz="0"/>
        </inertial>

        <visual>
            <origin xyz="RIGHTLOWERLEG_BOX_ORIGIN" rpy="0 0 0" />
            <geometry>
                <cylinder length="RIGHTLOWERLEGHEIGHT" radius="RIGHTLOWERLEGRADIUS"/>
            </geometry>
        </visual>

        <collision>
            <origin xyz="RIGHTLOWERLEG_BOX_ORIGIN" rpy="0 0 0" />
            <geometry>
                <cylinder length="RIGHTLOWERLEGHEIGHT" radius="RIGHTLOWERLEGRADIUS"/>
            </geometry>
        </collision>
    </link>
    <link name="RightFoot">
        <inertial>
            <mass value="RIGHTFOOTMASS"/>
            <origin xyz="RIGHTFOOT_COM_ORIGIN" rpy="0 0 0" />
            <inertia ixx="RIGHTFOOTINERTIAIXX" iyy="RIGHTFOOTINERTIAIYY" izz="RIGHTFOOTINERTIAIZZ" ixy="0" ixz="0" iyz="0"/>
        </inertial>

        <visual>
	    <origin xyz="RIGHTFOOT_BOX_ORIGIN" rpy="0 0 0" />
            <geometry>
                <box size="RIGHTFOOT_BOX_SIZE"/>
            </geometry>
        </visual>

        <collision>
		    <origin xyz="RIGHTFOOT_BOX_ORIGIN" rpy="0 0 0" />
	            <geometry>
	                <box size="RIGHTFOOT_BOX_SIZE"/>
	            </geometry>
        </collision>
    </link>   
    <link name="RightToe">
        <inertial>
            <mass value="RIGHTTOEMASS"/>
            <origin xyz="RIGHTTOE_COM_ORIGIN" rpy="0 0 0" />
            <inertia ixx="RIGHTTOEINERTIAIXX" iyy="RIGHTTOEINERTIAIYY" izz="RIGHTTOEINERTIAIZZ" ixy="0" ixz="0" iyz="0"/>
        </inertial>

        <visual>
            <origin xyz="RIGHTTOE_BOX_ORIGIN" rpy="0 0 0" />
            <geometry>
                <box size="RIGHTTOE_BOX_SIZE"/>
            </geometry>
        </visual>

        <collision>
            <origin xyz="RIGHTTOE_BOX_ORIGIN" rpy="0 0 0" />
            <geometry>
                <box size="RIGHTTOE_BOX_SIZE"/>
            </geometry>
        </collision>
    </link>
	<!--Chain from (20) to (23)-->
    <link name="LeftUpperLeg">
        <inertial>
            <mass value="LEFTUPPERLEGMASS"/>
            <origin xyz="LEFTUPPERLEG_COM_ORIGIN" rpy="0 0 0" />
            <inertia ixx="LEFTUPPERLEGINERTIAIXX" iyy="LEFTUPPERLEGINERTIAIYY" izz="LEFTUPPERLEGINERTIAIZZ" ixy="0" ixz="0" iyz="0"/>
        </inertial>

        <visual>
            <origin xyz="LEFTUPPERLEG_BOX_ORIGIN" rpy="0 0 0" />
            <geometry>
                <cylinder length="LEFTUPPERLEGHEIGHT" radius="LEFTUPPERLEGRADIUS"/>
            </geometry>
        </visual>

        <collision>
            <origin xyz="LEFTUPPERLEG_BOX_ORIGIN" rpy="0 0 0" />
            <geometry>
                <cylinder length="LEFTUPPERLEGHEIGHT" radius="LEFTUPPERLEGRADIUS"/>
            </geometry>
        </collision>
    </link>
	<link name="LeftLowerLeg">
        <inertial>
            <mass value="LEFTLOWERLEGMASS"/>
            <origin xyz="LEFTLOWERLEG_COM_ORIGIN" rpy="0 0 0" />
            <inertia ixx="LEFTLOWERLEGINERTIAIXX" iyy="LEFTLOWERLEGINERTIAIYY" izz="LEFTLOWERLEGINERTIAIZZ" ixy="0" ixz="0" iyz="0"/>
        </inertial>

        <visual>
            <origin xyz="LEFTLOWERLEG_BOX_ORIGIN" rpy="0 0 0" />
            <geometry>
		<cylinder length="LEFTLOWERLEGHEIGHT" radius="LEFTLOWERLEGRADIUS"/>
            </geometry>
        </visual>

        <collision>
            <origin xyz="LEFTLOWERLEG_BOX_ORIGIN" rpy="0 0 0" />
            <geometry>
		<cylinder length="LEFTLOWERLEGHEIGHT" radius="LEFTLOWERLEGRADIUS"/>
            </geometry>
        </collision>
    </link>
    <link name="LeftFoot">
        <inertial>
            <mass value="LEFTFOOTMASS"/>
            <origin xyz="LEFTFOOT_COM_ORIGIN" rpy="0 0 0" />
            <inertia ixx="LEFTFOOTINERTIAIXX" iyy="LEFTFOOTINERTIAIYY" izz="LEFTFOOTINERTIAIZZ" ixy="0" ixz="0" iyz="0"/>
        </inertial>

        <visual>
	    <origin xyz="LEFTFOOT_BOX_ORIGIN" rpy="0 0 0" />
            <geometry>
                <box size="LEFTFOOT_BOX_SIZE"/>
            </geometry>
        </visual>

        <collision>
		    <origin xyz="LEFTFOOT_BOX_ORIGIN" rpy="0 0 0" />
	            <geometry>
	                <box size="LEFTFOOT_BOX_SIZE"/>
	            </geometry>
        </collision>
    </link>
	<link name="LeftToe">
        <inertial>
            <mass value="LEFTTOEMASS"/>
            <origin xyz="LEFTTOE_COM_ORIGIN" rpy="0 0 0" />
            <inertia ixx="LEFTTOEINERTIAIXX" iyy="LEFTTOEINERTIAIYY" izz="LEFTTOEINERTIAIZZ" ixy="0" ixz="0" iyz="0"/>
        </inertial>

        <visual>
            <origin xyz="LEFTTOE_BOX_ORIGIN" rpy="0 0 0" />
            <geometry>
                <box size="LEFTTOE_BOX_SIZE"/>
            </geometry>
        </visual>

        <collision>
            <origin xyz="LEFTTOE_BOX_ORIGIN" rpy="0 0 0" />
            <geometry>
                <box size="LEFTTOE_BOX_SIZE"/>
            </geometry>
        </collision>
    </link>


	<!--JOINTS-->
	<joint name="jL5S1" type="revolute">
		<!--Origin of child frame wrt the parent frame-->
        <origin xyz="jL5S1_ORIGIN" rpy="0 0 0"/>
        <parent link="Pelvis"/>
        <child link="L5"/>
        <dynamics damping="0.1" friction="0.0"/>
        <limit effort="30" velocity="1.0" lower="-10.0" upper="10.0" />
        <axis xyz="0 1 0" />
    </joint>
	<joint name="jL4L3" type="revolute">
		<!--Origin of child frame wrt the parent frame-->
        <origin xyz="jL4L3_ORIGIN" rpy="0 0 0"/>
        <parent link="L5"/>
        <child link="L3"/>
        <dynamics damping="0.1" friction="0.0"/>
        <limit effort="30" velocity="1.0" lower="-10.0" upper="10.0" />
        <axis xyz="0 1 0" />
    </joint>
	<joint name="jL1T12" type="revolute">
		<!--Origin of child frame wrt the parent frame-->
        <origin xyz="jL1T12_ORIGIN" rpy="0 0 0"/>
        <parent link="L3"/>
        <child link="T12"/>
        <dynamics damping="0.1" friction="0.0"/>
        <limit effort="30" velocity="1.0" lower="-10.0" upper="10.0" />
        <axis xyz="0 1 0" />
    </joint>
	<joint name="jT9T8" type="revolute">
		<!--Origin of child frame wrt the parent frame-->
        <origin xyz="jT9T8_ORIGIN" rpy="0 0 0"/>
        <parent link="T12"/>
        <child link="T8"/>
        <dynamics damping="0.1" friction="0.0"/>
        <limit effort="30" velocity="1.0" lower="-10.0" upper="10.0" />
        <axis xyz="0 1 0" />
    </joint>	
	<joint name="jT1C7" type="revolute">
		<!--Origin of child frame wrt the parent frame-->
        <origin xyz="jT1C7_ORIGIN" rpy="0 0 0"/>
        <parent link="T8"/>
        <child link="Neck"/>
        <dynamics damping="0.1" friction="0.0"/>
        <limit effort="30" velocity="1.0" lower="-10.0" upper="10.0" />
        <axis xyz="0 1 0" />
    </joint>
	<joint name="jC1Head" type="revolute">
		<!--Origin of child frame wrt the parent frame-->
        <origin xyz="jC1Head_ORIGIN" rpy="0 0 0"/>
        <parent link="Neck"/>
        <child link="Head"/>
        <dynamics damping="0.1" friction="0.0"/>
        <limit effort="30" velocity="1.0" lower="-10.0" upper="10.0" />
        <axis xyz="0 0 1" />
    </joint>
	
	<joint name="jRightC7Shoulder" type="revolute">
		<!--Origin of child frame wrt the parent frame-->
        <origin xyz="jRightC7Shoulder_ORIGIN" rpy="0 0 0"/>
        <parent link="T8"/>
        <child link="RightShoulder"/>
        <dynamics damping="0.1" friction="0.0"/>
        <limit effort="30" velocity="1.0" lower="-10.0" upper="10.0" />
        <axis xyz="0 1 0" />
    </joint>
    <joint name="jRightShoulder" type="revolute">
		<!--Origin of child frame wrt the parent frame-->
        <origin xyz="jRightShoulder_ORIGIN" rpy="0 0 0"/>
        <parent link="RightShoulder"/>
        <child link="RightUpperArm"/>
        <dynamics damping="0.1" friction="0.0"/>
        <limit effort="30" velocity="1.0" lower="-10.0" upper="10.0" />
        <axis xyz="0 1 0" />
    </joint>	
    <joint name="jRightElbow" type="revolute">
		<!--Origin of child frame wrt the parent frame-->
        <origin xyz="jRightElbow_ORIGIN" rpy="0 0 0"/>
        <parent link="RightUpperArm"/>
        <child link="RightForeArm"/>
        <dynamics damping="0.1" friction="0.0"/>
        <limit effort="30" velocity="1.0" lower="-10.0" upper="10.0" />
        <axis xyz="0 1 0" />
    </joint>	
	<joint name="jRightWrist" type="revolute">
		<!--Origin of child frame wrt the parent frame-->
        <origin xyz="jRightWrist_ORIGIN" rpy="0 0 0"/>
        <parent link="RightForeArm"/>
        <child link="RightHand"/>
        <dynamics damping="0.1" friction="0.0"/>
        <limit effort="30" velocity="1.0" lower="-10.0" upper="10.0" />
        <axis xyz="0 1 0" />
    </joint>
	
	<joint name="jLeftC7Shoulder" type="revolute">
		<!--Origin of child frame wrt the parent frame-->
        <origin xyz="jLeftC7Shoulder_ORIGIN" rpy="0 0 0"/>
        <parent link="T8"/>
        <child link="LeftShoulder"/>
        <dynamics damping="0.1" friction="0.0"/>
        <limit effort="30" velocity="1.0" lower="-10.0" upper="10.0" />
        <axis xyz="0 1 0" />
    </joint>
    <joint name="jLeftShoulder" type="revolute">
		<!--Origin of child frame wrt the parent frame-->
        <origin xyz="jLeftShoulder_ORIGIN" rpy="0 0 0"/>
        <parent link="LeftShoulder"/>
        <child link="LeftUpperArm"/>
        <dynamics damping="0.1" friction="0.0"/>
        <limit effort="30" velocity="1.0" lower="-10.0" upper="10.0" />
        <axis xyz="0 1 0" />
    </joint>	
    <joint name="jLeftElbow" type="revolute">
		<!--Origin of child frame wrt the parent frame-->
        <origin xyz="jLeftElbow_ORIGIN" rpy="0 0 0"/>
        <parent link="LeftUpperArm"/>
        <child link="LeftForeArm"/>
        <dynamics damping="0.1" friction="0.0"/>
        <limit effort="30" velocity="1.0" lower="-10.0" upper="10.0" />
        <axis xyz="0 1 0" />
    </joint>	
	<joint name="jLeftWrist" type="revolute">
		<!--Origin of child frame wrt the parent frame-->
        <origin xyz="jLeftWrist_ORIGIN" rpy="0 0 0"/>
        <parent link="LeftForeArm"/>
        <child link="LeftHand"/>
        <dynamics damping="0.1" friction="0.0"/>
        <limit effort="30" velocity="1.0" lower="-10.0" upper="10.0" />
        <axis xyz="0 1 0" />
    </joint>
	
    <joint name="jRightHip" type="revolute">
		<!--Origin of child frame wrt the parent frame-->
        <origin xyz="jRightHip_ORIGIN" rpy="0 0 0"/>
        <parent link="Pelvis"/>
        <child link="RightUpperLeg"/>
        <dynamics damping="0.1" friction="0.0"/>
        <limit effort="30" velocity="1.0" lower="-10.0" upper="10.0" />
        <axis xyz="0 1 0" />
    </joint>
    <joint name="jRightKnee" type="revolute">
		<!--Origin of child frame wrt the parent frame-->
        <origin xyz="jRightKnee_ORIGIN" rpy="0 0 0"/>
        <parent link="RightUpperLeg"/>
        <child link="RightLowerLeg"/>
        <dynamics damping="0.1" friction="0.0"/>
        <limit effort="30" velocity="1.0" lower="-10.0" upper="10.0" />
        <axis xyz="0 1 0" />
    </joint>
    <joint name="jRightAnkle" type="revolute">
		<!--Origin of child frame wrt the parent frame-->
        <origin xyz="jRightAnkle_ORIGIN" rpy="0 0 0"/>
        <parent link="RightLowerLeg"/>
        <child link="RightFoot"/>
        <dynamics damping="0.1" friction="0.0"/>
        <limit effort="30" velocity="1.0" lower="-10.0" upper="10.0" />
        <axis xyz="0 1 0" />
    </joint>
	<joint name="jRightBallFoot" type="revolute">
		<!--Origin of child frame wrt the parent frame-->
        <origin xyz="jRightBallFoot_ORIGIN" rpy="0 0 0"/>
        <parent link="RightFoot"/>
        <child link="RightToe"/>
        <dynamics damping="0.1" friction="0.0"/>
        <limit effort="30" velocity="1.0" lower="-10.0" upper="10.0" />
        <axis xyz="0 1 0" />
    </joint>
	
    <joint name="jLeftHip" type="revolute">
		<!--Origin of child frame wrt the parent frame-->
        <origin xyz="jLeftHip_ORIGIN" rpy="0 0 0"/>
        <parent link="Pelvis"/>
        <child link="LeftUpperLeg"/>
        <dynamics damping="0.1" friction="0.0"/>
        <limit effort="30" velocity="1.0" lower="-10.0" upper="10.0" />
        <axis xyz="0 1 0" />
    </joint>
    <joint name="jLeftKnee" type="revolute">
		<!--Origin of child frame wrt the parent frame-->
        <origin xyz="jLeftKnee_ORIGIN" rpy="0 0 0"/>
        <parent link="LeftUpperLeg"/>
        <child link="LeftLowerLeg"/>
        <dynamics damping="0.1" friction="0.0"/>
        <limit effort="30" velocity="1.0" lower="-10.0" upper="10.0" />
        <axis xyz="0 1 0" />
    </joint>
	<joint name="jLeftAnkle" type="revolute">
		<!--Origin of child frame wrt the parent frame-->
        <origin xyz="jLeftAnkle_ORIGIN" rpy="0 0 0"/>
        <parent link="LeftLowerLeg"/>
        <child link="LeftFoot"/>
        <dynamics damping="0.1" friction="0.0"/>
        <limit effort="30" velocity="1.0" lower="-10.0" upper="10.0" />
        <axis xyz="0 1 0" />
    </joint>
	<joint name="jLeftBallFoot" type="revolute">
		<!--Origin of child frame wrt the parent frame-->
        <origin xyz="jLeftBallFoot_ORIGIN" rpy="0 0 0"/>
        <parent link="LeftFoot"/>
        <child link="LeftToe"/>
        <dynamics damping="0.1" friction="0.0"/>
        <limit effort="30" velocity="1.0" lower="-10.0" upper="10.0" />
        <axis xyz="0 1 0" />
    </joint>
	
</robot>