<robot name="XSensStyleModel_template">

    <link name="Ground">
        <inertial>
            <mass value="0"/>
            <origin xyz="0 0 0" rpy="0 0 0" />
            <inertia ixx="0" iyy="0" izz="0" ixy="0" ixz="0" iyz="0"/>
        </inertial>

        <visual>
	    <origin xyz="0 0 0" rpy="0 0 0" />
            <geometry>
                <box size="0.0001 0.0001 0.0001"/>
            </geometry>
        </visual>

        <collision>
	    <origin xyz="0 0 0" rpy="0 0 0" />
            <geometry>
                <box size="0.0001 0.0001 0.0001"/>
            </geometry>
        </collision>
    </link>
	
	<link name="LeftFoot">
        <inertial>
            <mass value="FOOTMASS"/>
            <origin xyz="0 0 FOOTHALFBETA" rpy="0 0 0" />
            <inertia ixx="FOOTINERTIAIXX" iyy="FOOTINERTIAIYY" izz="FOOTINERTIAIZZ" ixy="0" ixz="0" iyz="0"/>
        </inertial>

        <visual>
	    <origin xyz="0 0 FOOTHALFBETA" rpy="0 0 0" />
            <geometry>
                <box size="FOOTGAMMA FOOTALFA FOOTBETA"/>
            </geometry>
        </visual>

        <collision>
	    <origin xyz="0 0 FOOTHALFBETA" rpy="0 0 0" />
            <geometry>
                <box size="FOOTGAMMA FOOTALFA FOOTBETA"/>
            </geometry>
        </collision>
    </link>
	
	<link name="LeftToe">
        <inertial>
            <mass value="TOEMASS"/>
            <origin xyz="TOEHALFGAMMA 0 0" rpy="0 0 0" />
            <inertia ixx="TOEINERTIAIXX" iyy="TOEINERTIAIYY" izz="TOEINERTIAIZZ" ixy="0" ixz="0" iyz="0"/>
        </inertial>

        <visual>
            <origin xyz="TOEHALFGAMMA 0 0" rpy="0 0 0" />
            <geometry>
                <box size="TOEGAMMA TOEALFA TOEBETA"/>
            </geometry>
        </visual>

        <collision>
            <origin xyz="TOEHALFGAMMA 0 0" rpy="0 0 0" />
            <geometry>
                <box size="TOEGAMMA TOEALFA TOEBETA"/>
            </geometry>
        </collision>
    </link>

    <link name="LeftLowerLeg">
        <inertial>
            <mass value="LOWERLEGMASS"/>
            <origin xyz="0 0 LOWERLEGHALFHEIGHT" rpy="0 0 0" />
            <inertia ixx="LOWERLEGINERTIAIXX" iyy="LOWERLEGINERTIAIYY" izz="LOWERLEGINERTIAIZZ" ixy="0" ixz="0" iyz="0"/>
        </inertial>

        <visual>
            <origin xyz="0 0 LOWERLEGHALFHEIGHT" rpy="0 0 0" />
            <geometry>
		<cylinder length="LOWERLEGHEIGHT" radius="LOWERLEGRADIUS"/>
            </geometry>
        </visual>

        <collision>
            <origin xyz="0 0 LOWERLEGHALFHEIGHT" rpy="0 0 0" />
            <geometry>
                <cylinder length="LOWERLEGHEIGHT" radius="LOWERLEGRADIUS"/>
            </geometry>
        </collision>
    </link>
    
    <link name="LeftUpperLeg">
        <inertial>
            <mass value="UPPERLEGMASS"/>
            <origin xyz="0 0 UPPERLEGHALFHEIGHT" rpy="0 0 0" />
            <inertia ixx="UPPERLEGINERTIAIXX" iyy="UPPERLEGINERTIAIYY" izz="UPPERLEGINERTIAIZZ" ixy="0" ixz="0" iyz="0"/>
        </inertial>

        <visual>
            <origin xyz="0 0 UPPERLEGHALFHEIGHT" rpy="0 0 0" />
            <geometry>
                <cylinder length="UPPERLEGHEIGHT" radius="UPPERLEGRADIUS"/>
            </geometry>
        </visual>

        <collision>
            <origin xyz="0 0 UPPERLEGHALFHEIGHT" rpy="0 0 0" />
            <geometry>
                <cylinder length="UPPERLEGHEIGHT" radius="UPPERLEGRADIUS"/>
            </geometry>
        </collision>
    </link>
	
	<link name="Pelvis">
        <inertial>
            <mass value="PELVISMASS"/>
            <origin xyz="0 -HIPPOSY PELVISHALFBETA" rpy="0 0 0" />
            <inertia ixx="PELVISINERTIAIXX" iyy="PELVISINERTIAIYY" izz="PELVISINERTIAIZZ" ixy="0" ixz="0" iyz="0"/>
        </inertial>

        <visual>
            <origin xyz="0 -HIPPOSY PELVISHALFBETA" rpy="0 0 0" />
            <geometry>
                <box size="PELVISGAMMA PELVISALFA PELVISBETA"/>
            </geometry>
        </visual>

        <collision>
            <origin xyz="0 -HIPPOSY PELVISHALFBETA" rpy="0 0 0" />
            <geometry>
                <box size="PELVISGAMMA PELVISALFA PELVISBETA"/>
            </geometry>
        </collision>
    </link>

	<link name="L5">
        <inertial>
            <mass value="L5MASS"/>
            <origin xyz="0 0 L5HALFHEIGHT" rpy="0 0 0" />
            <inertia ixx="L5INERTIAIXX" iyy="L5INERTIAIYY" izz="L5INERTIAIZZ" ixy="0" ixz="0" iyz="0"/>
        </inertial>

        <visual>
            <origin xyz="0 0 L5HALFHEIGHT" rpy="0 0 0" />
            <geometry>
                <box size="L5DIAMETERX L5DIAMETERY L5HEIGHT"/>
            </geometry>
        </visual>

        <collision>
            <origin xyz="0 0 L5HALFHEIGHT" rpy="0 0 0" />
            <geometry>
                <box size="L5DIAMETERX L5DIAMETERY L5HEIGHT"/>
            </geometry>
        </collision>
    </link>
	
	<link name="L3">
        <inertial>
            <mass value="L3MASS"/>
            <origin xyz="0 0 L3HALFHEIGHT" rpy="0 0 0" />
            <inertia ixx="L3INERTIAIXX" iyy="L3INERTIAIYY" izz="L3INERTIAIZZ" ixy="0" ixz="0" iyz="0"/>
        </inertial>

        <visual>
            <origin xyz="0 0 L3HALFHEIGHT" rpy="0 0 0" />
            <geometry>
                <box size="L3DIAMETERX L3DIAMETERY L3HEIGHT"/>
            </geometry>
        </visual>

        <collision>
            <origin xyz="0 0 L3HALFHEIGHT" rpy="0 0 0" />
            <geometry>
                <box size="L3DIAMETERX L3DIAMETERY L3HEIGHT"/>
            </geometry>
        </collision>
    </link>
	
	<link name="T12">
        <inertial>
            <mass value="T12MASS"/>
            <origin xyz="0 0 T12HALFHEIGHT" rpy="0 0 0" />
            <inertia ixx="T12INERTIAIXX" iyy="T12INERTIAIYY" izz="T12INERTIAIZZ" ixy="0" ixz="0" iyz="0"/>
        </inertial>

        <visual>
            <origin xyz="0 0 T12HALFHEIGHT" rpy="0 0 0" />
            <geometry>
                <box size="T12DIAMETERX T12DIAMETERY T12HEIGHT"/>
            </geometry>
        </visual>

        <collision>
            <origin xyz="0 0 T12HALFHEIGHT" rpy="0 0 0" />
            <geometry>
                <box size="T12DIAMETERX T12DIAMETERY T12HEIGHT"/>
            </geometry>
        </collision>
    </link>
	
	<link name="T8">
        <inertial>
            <mass value="T8MASS"/>
            <origin xyz="0 0 T8HALFBETA" rpy="0 0 0" />
            <inertia ixx="T8INERTIAIXX" iyy="T8INERTIAIYY" izz="T8INERTIAIZZ" ixy="0" ixz="0" iyz="0"/>
        </inertial>

        <visual>
            <origin xyz="0 0 T8HALFBETA" rpy="0 0 0" />
            <geometry>
                <box size="T8GAMMA T8ALFA T8BETA"/>
            </geometry>
        </visual>

        <collision>
            <origin xyz="0 0 T8HALFBETA" rpy="0 0 0" />
            <geometry>
                <box size="T8GAMMA T8ALFA T8BETA"/>
            </geometry>
        </collision>
    </link>
	
    <link name="Neck">
        <inertial>
            <mass value="NECKMASS"/>
            <origin xyz="0 0 NECKHALFHEIGHT" rpy="0 0 0" />
            <inertia ixx="NECKINERTIAIXX" iyy="NECKINERTIAIYY" izz="NECKINERTIAIZZ" ixy="0" ixz="0" iyz="0"/>
        </inertial>

        <visual>
            <origin xyz="0 0 NECKHALFHEIGHT" rpy="0 0 0" />
            <geometry>
		<cylinder length="NECKHEIGHT" radius="NECKRADIUS"/>
            </geometry>
        </visual>

        <collision>
            <origin xyz="0 0 NECKHALFHEIGHT" rpy="0 0 0" />
            <geometry>
                <cylinder length="NECKHEIGHT" radius="NECKRADIUS"/>
            </geometry>
        </collision>
    </link>	
	
	<link name="Head">
        <inertial>
            <mass value="HEADMASS"/>
            <origin xyz="0 0 HEADRADIUS" rpy="0 0 0" />
            <inertia ixx="HEADINERTIAIXX" iyy="HEADINERTIAIYY" izz="HEADINERTIAIZZ" ixy="0" ixz="0" iyz="0"/>
        </inertial>

        <visual>
            <origin xyz="0 0 HEADRADIUS" rpy="0 0 0" />
            <geometry>
                <sphere radius="HEADRADIUS"/>
            </geometry>
        </visual>

        <collision>
            <origin xyz="0 0 HEADRADIUS" rpy="0 0 0" />
            <geometry>
                <sphere radius="HEADRADIUS"/>
            </geometry>
        </collision>
    </link>
	
    <link name="RightUpperLeg">
        <inertial>
            <mass value="UPPERLEGMASS"/>
            <origin xyz="0 0 -UPPERLEGHALFHEIGHT" rpy="0 0 0" />
            <inertia ixx="UPPERLEGINERTIAIXX" iyy="UPPERLEGINERTIAIYY" izz="UPPERLEGINERTIAIZZ" ixy="0" ixz="0" iyz="0"/>
        </inertial>

        <visual>
            <origin xyz="0 0 -UPPERLEGHALFHEIGHT" rpy="0 0 0" />
            <geometry>
                <cylinder length="UPPERLEGHEIGHT" radius="UPPERLEGRADIUS"/>
            </geometry>
        </visual>

        <collision>
            <origin xyz="0 0 -UPPERLEGHALFHEIGHT" rpy="0 0 0" />
            <geometry>
                <cylinder length="UPPERLEGHEIGHT" radius="UPPERLEGRADIUS"/>
            </geometry>
        </collision>
    </link>


    <link name="RightLowerLeg">
        <inertial>
            <mass value="LOWERLEGMASS"/>
            <origin xyz="0 0 -LOWERLEGHALFHEIGHT" rpy="0 0 0" />
            <inertia ixx="LOWERLEGINERTIAIXX" iyy="LOWERLEGINERTIAIYY" izz="LOWERLEGINERTIAIZZ" ixy="0" ixz="0" iyz="0"/>
        </inertial>

        <visual>
            <origin xyz="0 0 -LOWERLEGHALFHEIGHT" rpy="0 0 0" />
            <geometry>
                <cylinder length="LOWERLEGHEIGHT" radius="LOWERLEGRADIUS"/>
            </geometry>
        </visual>

        <collision>
            <origin xyz="0 0 -LOWERLEGHALFHEIGHT" rpy="0 0 0" />
            <geometry>
                <cylinder length="LOWERLEGHEIGHT" radius="LOWERLEGRADIUS"/>
            </geometry>
        </collision>
    </link>


    <link name="RightFoot">
        <inertial>
            <mass value="FOOTMASS"/>
            <origin xyz="ANKLEPOSX 0 -FOOTHALFBETA" rpy="0 0 0" />
            <inertia ixx="FOOTINERTIAIXX" iyy="FOOTINERTIAIYY" izz="FOOTINERTIAIZZ" ixy="0" ixz="0" iyz="0"/>
        </inertial>

        <visual>
	    <origin xyz="ANKLEPOSX 0 -FOOTHALFBETA" rpy="0 0 0" />
            <geometry>
                <box size="FOOTGAMMA FOOTALFA FOOTBETA"/>
            </geometry>
        </visual>

        <collision>
	    <origin xyz="ANKLEPOSX 0 -FOOTHALFBETA" rpy="0 0 0" />
            <geometry>
                <box size="FOOTGAMMA FOOTALFA FOOTBETA"/>
            </geometry>
        </collision>
    </link>
        
    <link name="RightToe">
        <inertial>
            <mass value="TOEMASS"/>
            <origin xyz="TOEHALFGAMMA 0 0" rpy="0 0 0" />
            <inertia ixx="TOEINERTIAIXX" iyy="TOEINERTIAIYY" izz="TOEINERTIAIZZ" ixy="0" ixz="0" iyz="0"/>
        </inertial>

        <visual>
            <origin xyz="TOEHALFGAMMA 0 0" rpy="0 0 0" />
            <geometry>
                <box size="TOEGAMMA TOEALFA TOEBETA"/>
            </geometry>
        </visual>

        <collision>
            <origin xyz="TOEHALFGAMMA 0 0" rpy="0 0 0" />
            <geometry>
                <box size="TOEGAMMA TOEALFA TOEBETA"/>
            </geometry>
        </collision>
    </link>
	
	<link name="LeftShoulder">
        <inertial>
            <mass value="SHOULDERMASS"/>
            <origin xyz="0 SHOULDERHALFHEIGHT 0" rpy="0 0 0" />
            <inertia ixx="SHOULDERINERTIAIXX" iyy="SHOULDERINERTIAIYY" izz="SHOULDERINERTIAIZZ" ixy="0" ixz="0" iyz="0"/>
        </inertial>

        <visual>
            <origin xyz="0 SHOULDERHALFHEIGHT 0" rpy="0 0 0" />
            <geometry>
                <box size="SHOULDERDIAMETER SHOULDERHEIGHT SHOULDERDIAMETER"/>
            </geometry>
        </visual>

        <collision>
            <origin xyz="0 SHOULDERHALFHEIGHT 0" rpy="0 0 0" />
            <geometry>
                <box size="SHOULDERDIAMETER SHOULDERHEIGHT SHOULDERDIAMETER"/>
            </geometry>
        </collision>
    </link>
	
    <link name="LeftUpperArm">
        <inertial>
            <mass value="UPPERARMMASS"/>
            <origin xyz="0 UPPERARMRADIUS -ARMPOSZ" rpy="0 0 0" />
            <inertia ixx="UPPERARMINERTIAIXX" iyy="UPPERARMINERTIAIYY" izz="UPPERARMINERTIAIZZ" ixy="0" ixz="0" iyz="0"/>
        </inertial>

        <visual>
            <origin xyz="0 UPPERARMRADIUS -ARMPOSZ" rpy="0 0 0" />
            <geometry>
                <cylinder length="UPPERARMHEIGHT" radius="UPPERARMRADIUS"/>
            </geometry>
        </visual>

        <collision>
            <origin xyz="0 UPPERARMRADIUS -ARMPOSZ" rpy="0 0 0" />
            <geometry>
                <cylinder length="UPPERARMHEIGHT" radius="UPPERARMRADIUS"/>
            </geometry>
        </collision>
    </link>	
	
	<link name="LeftForeArm">
        <inertial>
            <mass value="FOREARMMASS"/>
            <origin xyz="0 0 -FOREARMHALFHEIGHT" rpy="0 0 0" />
            <inertia ixx="FOREARMINERTIAIXX" iyy="FOREARMINERTIAIYY" izz="FOREARMINERTIAIZZ" ixy="0" ixz="0" iyz="0"/>
        </inertial>

        <visual>
            <origin xyz="0 0 -FOREARMHALFHEIGHT" rpy="0 0 0" />
            <geometry>
                <cylinder length="FOREARMHEIGHT" radius="FOREARMRADIUS"/>
            </geometry>
        </visual>

        <collision>
            <origin xyz="0 0 -FOREARMHALFHEIGHT" rpy="0 0 0" />
            <geometry>
                <cylinder length="FOREARMHEIGHT" radius="FOREARMRADIUS"/>
            </geometry>
        </collision>
    </link>
	
	<link name="LeftHand">
        <inertial>
            <mass value="HANDMASS"/>
            <origin xyz="0 0 -HANDHALFBETA" rpy="0 0 0" />
            <inertia ixx="HANDINERTIAIXX" iyy="HANDINERTIAIYY" izz="HANDINERTIAIZZ" ixy="0" ixz="0" iyz="0"/>
        </inertial>

        <visual>
            <origin xyz="0 0 -HANDHALFBETA" rpy="0 0 0" />
            <geometry>
                <box size="HANDGAMMA HANDALFA HANDBETA"/>
            </geometry>
        </visual>

        <collision>
            <origin xyz="0 0 -HANDHALFBETA" rpy="0 0 0" />
            <geometry>
                <box size="HANDGAMMA HANDALFA HANDBETA"/>
            </geometry>
        </collision>
    </link>
	
	<link name="RightShoulder">
        <inertial>
            <mass value="SHOULDERMASS"/>
            <origin xyz="0 -SHOULDERHALFHEIGHT 0" rpy="0 0 0" />
            <inertia ixx="SHOULDERINERTIAIXX" iyy="SHOULDERINERTIAIYY" izz="SHOULDERINERTIAIZZ" ixy="0" ixz="0" iyz="0"/>
        </inertial>

        <visual>
            <origin xyz="0 -SHOULDERHALFHEIGHT 0" rpy="0 0 0" />
            <geometry>
                <box size="SHOULDERDIAMETER SHOULDERHEIGHT SHOULDERDIAMETER"/>
            </geometry>
        </visual>

        <collision>
            <origin xyz="0 -SHOULDERHALFHEIGHT 0" rpy="0 0 0" />
            <geometry>
                <box size="SHOULDERDIAMETER SHOULDERHEIGHT SHOULDERDIAMETER"/>
            </geometry>
        </collision>
    </link>
	
    <link name="RightUpperArm">
        <inertial>
            <mass value="UPPERARMMASS"/>
            <origin xyz="0 -UPPERARMRADIUS -ARMPOSZ" rpy="0 0 0" />
            <inertia ixx="UPPERARMINERTIAIXX" iyy="UPPERARMINERTIAIYY" izz="UPPERARMINERTIAIZZ" ixy="0" ixz="0" iyz="0"/>
        </inertial>

        <visual>
            <origin xyz="0 -UPPERARMRADIUS -ARMPOSZ" rpy="0 0 0" />
            <geometry>
                <cylinder length="UPPERARMHEIGHT" radius="UPPERARMRADIUS"/>
            </geometry>
        </visual>

        <collision>
            <origin xyz="0 -UPPERARMRADIUS -ARMPOSZ" rpy="0 0 0" />
            <geometry>
                <cylinder length="UPPERARMHEIGHT" radius="UPPERARMRADIUS"/>
            </geometry>
        </collision>
    </link>	
	
	<link name="RightForeArm">
        <inertial>
            <mass value="FOREARMMASS"/>
            <origin xyz="0 0 -FOREARMHALFHEIGHT" rpy="0 0 0" />
            <inertia ixx="FOREARMINERTIAIXX" iyy="FOREARMINERTIAIYY" izz="FOREARMINERTIAIZZ" ixy="0" ixz="0" iyz="0"/>
        </inertial>

        <visual>
            <origin xyz="0 0 -FOREARMHALFHEIGHT" rpy="0 0 0" />
            <geometry>
                <cylinder length="FOREARMHEIGHT" radius="FOREARMRADIUS"/>
            </geometry>
        </visual>

        <collision>
            <origin xyz="0 0 -FOREARMHALFHEIGHT" rpy="0 0 0" />
            <geometry>
                <cylinder length="FOREARMHEIGHT" radius="FOREARMRADIUS"/>
            </geometry>
        </collision>
    </link>
	
	<link name="RightHand">
        <inertial>
            <mass value="HANDMASS"/>
            <origin xyz="0 0 -HANDHALFBETA" rpy="0 0 0" />
            <inertia ixx="HANDINERTIAIXX" iyy="HANDINERTIAIYY" izz="HANDINERTIAIZZ" ixy="0" ixz="0" iyz="0"/>
        </inertial>

        <visual>
            <origin xyz="0 0 -HANDHALFBETA" rpy="0 0 0" />
            <geometry>
                <box size="HANDGAMMA HANDALFA HANDBETA"/>
            </geometry>
        </visual>

        <collision>
            <origin xyz="0 0 -HANDHALFBETA" rpy="0 0 0" />
            <geometry>
                <box size="HANDGAMMA HANDALFA HANDBETA"/>
            </geometry>
        </collision>
    </link>
	
	
    <joint name="jGround_LeftFoot" type="fixed">
        <origin xyz="0 0 0" rpy="0 0 0"/>
        <parent link="Ground"/>
        <child link="LeftFoot"/>
    </joint>       
	
	<joint name="jLeftBallFoot" type="revolute">
        <origin xyz="FOOTHALFGAMMA 0 FOOTHALFBETA" rpy="0 0 0"/>
        <parent link="LeftFoot"/>
        <child link="LeftToe"/>
        <dynamics damping="0.1" friction="0.0"/>
        <limit effort="30" velocity="1.0" lower="-10.0" upper="10.0" />
        <axis xyz="0 1 0" />
    </joint>

    <joint name="jLeftAnkle" type="revolute">
        <origin xyz="-ANKLEPOSX 0 FOOTBETA" rpy="0 0 0"/>
        <parent link="LeftFoot"/>
        <child link="LeftLowerLeg"/>
        <dynamics damping="0.1" friction="0.0"/>
        <limit effort="30" velocity="1.0" lower="-10.0" upper="10.0" />
        <axis xyz="0 1 0" />
    </joint>


    <joint name="jLeftKnee" type="revolute">
        <origin xyz="0 0 LOWERLEGHEIGHT" rpy="0 0 0"/>
        <parent link="LeftLowerLeg"/>
        <child link="LeftUpperLeg"/>
        <dynamics damping="0.1" friction="0.0"/>
        <limit effort="30" velocity="1.0" lower="-10.0" upper="10.0" />
        <axis xyz="0 1 0" />
    </joint>
    
    <joint name="jLeftHip" type="revolute">
        <origin xyz="0 0 UPPERLEGHEIGHT" rpy="0 0 0"/>
        <parent link="LeftUpperLeg"/>
        <child link="Pelvis"/>
        <dynamics damping="0.1" friction="0.0"/>
        <limit effort="30" velocity="1.0" lower="-10.0" upper="10.0" />
        <axis xyz="0 1 0" />
    </joint>

	<joint name="jL5S1" type="revolute">
        <origin xyz="0 -HIPPOSY PELVISBETA" rpy="0 0 0"/>
        <parent link="Pelvis"/>
        <child link="L5"/>
        <dynamics damping="0.1" friction="0.0"/>
        <limit effort="30" velocity="1.0" lower="-10.0" upper="10.0" />
        <axis xyz="0 1 0" />
    </joint>
	
	<joint name="jL4L3" type="revolute">
        <origin xyz="0 0 L5HEIGHT" rpy="0 0 0"/>
        <parent link="L5"/>
        <child link="L3"/>
        <dynamics damping="0.1" friction="0.0"/>
        <limit effort="30" velocity="1.0" lower="-10.0" upper="10.0" />
        <axis xyz="0 1 0" />
    </joint>
	
	<joint name="jL1T12" type="revolute">
        <origin xyz="0 0 L3HEIGHT" rpy="0 0 0"/>
        <parent link="L3"/>
        <child link="T12"/>
        <dynamics damping="0.1" friction="0.0"/>
        <limit effort="30" velocity="1.0" lower="-10.0" upper="10.0" />
        <axis xyz="0 1 0" />
    </joint>
	
	<joint name="jT9T8" type="revolute">
        <origin xyz="0 0 T12HEIGHT" rpy="0 0 0"/>
        <parent link="T12"/>
        <child link="T8"/>
        <dynamics damping="0.1" friction="0.0"/>
        <limit effort="30" velocity="1.0" lower="-10.0" upper="10.0" />
        <axis xyz="0 1 0" />
    </joint>	
	
	<joint name="jT1C7" type="revolute">
        <origin xyz="0 0 T8BETA" rpy="0 0 0"/>
        <parent link="T8"/>
        <child link="Neck"/>
        <dynamics damping="0.1" friction="0.0"/>
        <limit effort="30" velocity="1.0" lower="-10.0" upper="10.0" />
        <axis xyz="0 1 0" />
    </joint>	
	
	<joint name="jC1Head" type="revolute">
        <origin xyz="0 0 NECKHEIGHT" rpy="0 0 0"/>
        <parent link="Neck"/>
        <child link="Head"/>
        <dynamics damping="0.1" friction="0.0"/>
        <limit effort="30" velocity="1.0" lower="-10.0" upper="10.0" />
        <axis xyz="0 0 1" />
    </joint>
	
    <joint name="jRightHip" type="revolute">
        <origin xyz="0 -HIPDOUBLEPOSY 0" rpy="0 0 0"/>
        <parent link="Pelvis"/>
        <child link="RightUpperLeg"/>
        <dynamics damping="0.1" friction="0.0"/>
        <limit effort="30" velocity="1.0" lower="-10.0" upper="10.0" />
        <axis xyz="0 1 0" />
    </joint>

    <joint name="jRightKnee" type="revolute">
        <origin xyz="0 0 -UPPERLEGHEIGHT" rpy="0 0 0"/>
        <parent link="RightUpperLeg"/>
        <child link="RightLowerLeg"/>
        <dynamics damping="0.1" friction="0.0"/>
        <limit effort="30" velocity="1.0" lower="-10.0" upper="10.0" />
        <axis xyz="0 1 0" />
    </joint>

    <joint name="jRightAnkle" type="revolute">
        <origin xyz="0 0 -LOWERLEGHEIGHT" rpy="0 0 0"/>
        <parent link="RightLowerLeg"/>
        <child link="RightFoot"/>
        <dynamics damping="0.1" friction="0.0"/>
        <limit effort="30" velocity="1.0" lower="-10.0" upper="10.0" />
        <axis xyz="0 1 0" />
    </joint>
	
	<joint name="jRightBallFoot" type="revolute">
        <origin xyz="TOEPOSX 0 -FOOTHALFBETA" rpy="0 0 0"/>
        <parent link="RightFoot"/>
        <child link="RightToe"/>
        <dynamics damping="0.1" friction="0.0"/>
        <limit effort="30" velocity="1.0" lower="-10.0" upper="10.0" />
        <axis xyz="0 1 0" />
    </joint>

	<joint name="jLeftC7Shoulder" type="revolute">
        <origin xyz="0 T8HALFALFA SHOULDERURDFPOSZ" rpy="0 0 0"/>
        <parent link="T8"/>
        <child link="LeftShoulder"/>
        <dynamics damping="0.1" friction="0.0"/>
        <limit effort="30" velocity="1.0" lower="-10.0" upper="10.0" />
        <axis xyz="0 1 0" />
    </joint>

    <joint name="jLeftShoulder" type="revolute">
        <origin xyz="0 SHOULDERHEIGHT 0" rpy="0 0 0"/>
        <parent link="LeftShoulder"/>
        <child link="LeftUpperArm"/>
        <dynamics damping="0.1" friction="0.0"/>
        <limit effort="30" velocity="1.0" lower="-10.0" upper="10.0" />
        <axis xyz="0 1 0" />
    </joint>	
	
    <joint name="jLeftElbow" type="revolute">
        <origin xyz="0 UPPERARMRADIUS -ARMURDFPOSZ" rpy="0 0 0"/>
        <parent link="LeftUpperArm"/>
        <child link="LeftForeArm"/>
        <dynamics damping="0.1" friction="0.0"/>
        <limit effort="30" velocity="1.0" lower="-10.0" upper="10.0" />
        <axis xyz="0 1 0" />
    </joint>	
	
	<joint name="jLeftWrist" type="revolute">
        <origin xyz="0 0 -FOREARMHEIGHT" rpy="0 0 0"/>
        <parent link="LeftForeArm"/>
        <child link="LeftHand"/>
        <dynamics damping="0.1" friction="0.0"/>
        <limit effort="30" velocity="1.0" lower="-10.0" upper="10.0" />
        <axis xyz="0 1 0" />
    </joint>
	
	<joint name="jRightC7Shoulder" type="revolute">
        <origin xyz="0 -T8HALFALFA SHOULDERURDFPOSZ" rpy="0 0 0"/>
        <parent link="T8"/>
        <child link="RightShoulder"/>
        <dynamics damping="0.1" friction="0.0"/>
        <limit effort="30" velocity="1.0" lower="-10.0" upper="10.0" />
        <axis xyz="0 1 0" />
    </joint>

    <joint name="jRightShoulder" type="revolute">
        <origin xyz="0 -SHOULDERHEIGHT 0" rpy="0 0 0"/>
        <parent link="RightShoulder"/>
        <child link="RightUpperArm"/>
        <dynamics damping="0.1" friction="0.0"/>
        <limit effort="30" velocity="1.0" lower="-10.0" upper="10.0" />
        <axis xyz="0 1 0" />
    </joint>	
	
    <joint name="jRightElbow" type="revolute">
        <origin xyz="0 -UPPERARMRADIUS -ARMURDFPOSZ" rpy="0 0 0"/>
        <parent link="RightUpperArm"/>
        <child link="RightForeArm"/>
        <dynamics damping="0.1" friction="0.0"/>
        <limit effort="30" velocity="1.0" lower="-10.0" upper="10.0" />
        <axis xyz="0 1 0" />
    </joint>	
	
	<joint name="jRightWrist" type="revolute">
        <origin xyz="0 0 -FOREARMHEIGHT" rpy="0 0 0"/>
        <parent link="RightForeArm"/>
        <child link="RightHand"/>
        <dynamics damping="0.1" friction="0.0"/>
        <limit effort="30" velocity="1.0" lower="-10.0" upper="10.0" />
        <axis xyz="0 1 0" />
    </joint>
	
</robot>