<robot name="threeLinkHuman">
    <link name="foot">
        <inertial>
            <mass value="3.0639"/>
            <origin xyz="0 0 0.030877" rpy="0 0 0" />
            <inertia ixx="0.0051523" iyy="0.014672" izz="0.017877" ixy="0" ixz="0" iyz="0"/>
        </inertial>

        <visual>
			<origin xyz="0 0 0.030877" rpy="0 0 0" />
            <geometry>
                <box size="0.23162 0.12793 0.061755"/>
            </geometry>
        </visual>

        <collision>
			<origin xyz="0 0 0.030877" rpy="0 0 0" />
            <geometry>
                <box size="0.23162 0.12793 0.061755"/>
            </geometry>
        </collision>
    </link>
    
    <link name="leg">
        <inertial>
            <mass value="25.5563"/>
            <origin xyz="0 0 0.3985" rpy="0 0 0" />
            <inertia ixx="1.411" iyy="1.3813" izz="0.086802" ixy="0" ixz="0" iyz="0"/>
        </inertial>

        <visual>
            <origin xyz="0 0 0.3985" rpy="0 0 0" />
            <geometry>
                <box size="0.11581 0.16536 0.79699"/>
            </geometry>
        </visual>

        <collision>
            <origin xyz="0 0 0.3985" rpy="0 0 0" />
            <geometry>
                <box size="0.11581 0.16536 0.79699"/>
            </geometry>
        </collision>
    </link>
    
    <link name="torso">
        <inertial>
            <mass value="33.0707"/>
            <origin xyz="0 0 0.26923" rpy="0 0 0" />
            <inertia ixx="1.0755" iyy="0.836" izz="0.31343" ixy="0" ixz="0" iyz="0"/>
        </inertial>

        <visual>
            <origin xyz="0 0 0.26923" rpy="0 0 0" />
            <geometry>
                <box size="0.11581 0.31673 0.53846"/>
            </geometry>
        </visual>

        <collision>
            <origin xyz="0 0 0.26923" rpy="0 0 0" />
            <geometry>
                <box size="0.11581 0.31673 0.53846"/>
            </geometry>
        </collision>
    </link>
        
    <joint name="ankle" type="revolute">
        <origin xyz="-0.057906 0 0.061755" rpy="0 0 0"/>
        <parent link="foot"/>
        <child link="leg"/>
        <dynamics damping="0.1" friction="0.0"/>
        <limit effort="30" velocity="1.0" lower="-10.0" upper="10.0" />
        <axis xyz="0 1 0" />
    </joint>
    
    <joint name="hip" type="revolute">
        <origin xyz="0 0 0.79699" rpy="0 0 0"/>
        <parent link="leg"/>
        <child link="torso"/>
        <dynamics damping="0.1" friction="0.0"/>
        <limit effort="30" velocity="1.0" lower="-10.0" upper="10.0" />
        <axis xyz="0 1 0" />
    </joint>

	<sensor name="imu_gyro" type="gyroscope">
		<parent link="torso"/>
		<origin xyz="0.1461 0.0455 0.2335" rpy="-0.0283 -1.3298 -3.1176" />
	</sensor>

	<sensor name="imu_acc" type="accelerometer">
		<parent link="torso"/>
		<origin xyz="0.1461 0.0455 0.2335" rpy="-0.0283 -1.3298 -3.1176" />
	</sensor>

</robot>
